Workbook

Sheet 2월
A1: 2월 | B1: 담당자 | C1: 매체분석 | I1: DB효율 | N1: 매출분석
C2: 작성시점 | D2: 노출량 | E2: 클릭 | F2: 클릭당 단가 (원) CPC (광고집행비/클릭) | G2: 클릭률 CTR (클릭/노출량) | H2: 주간 집행 광고비 | I2: DB수량 | J2: DB전환률 (DB수량/클릭) | K2: DB단가 (광고비/DB수량) | L2: 미팅전환 건수 | M2: 미팅전환률 (미팅건수/DB수량) | N2: 수당 매출 | O2: 클로징 건수 | P2: 비고 (고객이름, 아카데미 종류 등) | Q2: 클로징률 (클로징건수/DB수량) | R2: 순이익(원) | S2: ROAS (매출/광고비)*100 | T2: ROI (순이익/광고비)*100
A3: 2월 1주 2/1~2/7 (토~금) | B3: 맥스 | F3: =iferror(H3/E3,"") | G3: =iferror(E3/D3,"") | J3: =iferror(G3/C3,"") | K3: =iferror(H3/I3,"") | M3: =iferror(L3/I3,"") | Q3: =iferror(O3/I3,"") | R3: =iferror(N3-H3,"") -> 0 | S3: =iferror(N3/H3,"") | T3: =iferror(R3/H3,"")
B4: 해리 | C4: 45691 | F4: =iferror(H4/E4,"") | G4: =iferror(E4/D4,"") | J4: =iferror(G4/C4,"") -> 0 | K4: =iferror(H4/I4,"") | M4: =iferror(L4/I4,"") | N4: 500000 | O4: 2 | P4: 정아인(2명), 이종훈 | Q4: =iferror(O4/I4,"") | R4: =iferror(N4-H4,"") -> 500000 | S4: =iferror(N4/H4,"") | T4: =iferror(R4/H4,"")
B5: 로즈 | F5: =iferror(H5/E5,"") | G5: =iferror(E5/D5,"") | J5: =iferror(I5/E5,"") | K5: =iferror(H5/I5,"") | M5: =iferror(L5/I5,"")
B6: 페르 | F6: =iferror(H6/E6,"") | G6: =iferror(E6/D6,"") | J6: =iferror(G6/C6,"") | K6: =iferror(H6/I6,"") | M6: =iferror(L6/I6,"")
A7: 팀평균 | F7: =averageif(F3:F6,">0") -> #DIV/0! | G7: =averageif(G3:G6,">0") -> #DIV/0! | I7: =SUM(I3:I6) -> 0 | J7: =averageif(J3:J6,">0") -> #DIV/0! | K7: =averageif(K3:K6,">0") -> #DIV/0! | M7: =averageif(M3:M6,">0") -> #DIV/0! | N7: =SUM(N3:N6) -> 500000 | O7: =SUM(O3:O6) -> 2 | Q7: =averageif(Q3:Q6,">0") -> #DIV/0! | S7: =averageif(S3:S6,">0") -> #DIV/0! | T7: =averageif(T3:T6,">0") -> #DIV/0!
B9: 담당자 | C9: 매체분석 | I9: DB효율 | N9: 매출분석
C10: 작성시점 | D10: 노출량 | E10: 클릭 | F10: 클릭당 단가 (원) CPC (광고집행비/클릭) | G10: 클릭률 CTR (클릭/노출량) | H10: 주간 집행 광고비 | I10: DB수량 | J10: DB전환률 (DB수량/클릭) | K10: DB단가 (광고비/DB수량) | L10: 미팅전환 건수 | M10: 미팅전환률 (미팅건수/DB수량) | N10: 수당 매출 | O10: 클로징 건수 | P10: 비고 (고객이름, 메모 등) | Q10: 클로징률 (클로징건수/DB수량) | R10: 순이익(원) | S10: ROAS (매출/광고비)*100 | T10: ROI (순이익/광고비)*100
A11: 2월 2주 2/8~2/14 (토~금) | B11: 맥스 | G11: =iferror(E11/D11,"") | J11: =iferror(G11/C11,"") | K11: =iferror(H11/I11,"") | M11: =iferror(L11/I11,"") | Q11: =iferror(O11/I11,"") | R11: =iferror(N11-H11,"") -> 0 | S11: =iferror(N11/H11,"") | T11: =iferror(R11/H11,"")
B12: 해리 | F12: =iferror(H12/E12,"") | G12: =iferror(E12/D12,"") | J12: =iferror(I12/E12,"") | K12: =iferror(H12/I12,"") | M12: =iferror(L12/I12,"") | N12: 100000 | O12: 1 | P12: 이재명(2명) | Q12: =iferror(O12/I12,"") | R12: =iferror(N12-H12,"") -> 100000 | S12: =iferror(N12/H12,"") | T12: =iferror(R12/H12,"")
B13: 로즈 | F13: =iferror(H13/E13,"") | G13: =iferror(E13/D13,"") | J13: =iferror(I13/E13,"") | K13: =iferror(H13/I13,"") | M13: =iferror(L13/I13,"") | Q13: =iferror(O13/I13,"") | R13: =iferror(N13-H13,"") -> 0 | S13: =iferror(N13/H13,"") | T13: =iferror(R13/H13,"")
B14: 페르 | F14: =iferror(H14/E14,"") | G14: =iferror(E14/D14,"") | J14: =iferror(G14/C14,"") | K14: =iferror(H14/I14,"") | M14: =iferror(L14/I14,"") | Q14: =iferror(O14/I14,"") | R14: =iferror(N14-H14,"") -> 0 | S14: =iferror(N14/H14,"") | T14: =iferror(R14/H14,"")
A15: 팀평균 | F15: =averageif(F11:F14,">0") -> #DIV/0! | G15: =averageif(G11:G14,">0") -> #DIV/0! | I15: =SUM(I11:I14) -> 0 | J15: =averageif(J11:J14,">0") -> #DIV/0! | K15: =averageif(K11:K14,">0") -> #DIV/0! | M15: =averageif(M11:M14,">0") -> #DIV/0! | N15: =SUM(N11:N14) -> 100000 | O15: =SUM(O11:O14) -> 1 | Q15: =averageif(Q11:Q14,">0") -> #DIV/0! | S15: =averageif(S11:S14,">0") -> #DIV/0! | T15: =averageif(T11:T14,">0") -> #DIV/0!
B17: 담당자 | C17: 매체분석 | I17: DB효율 | N17: 매출분석
C18: 작성시점 | D18: 노출량 | E18: 클릭 | F18: 클릭당 단가 (원) CPC (광고집행비/클릭) | G18: 클릭률 CTR (클릭/노출량) | H18: 주간 집행 광고비 | I18: DB수량 | J18: DB전환률 (DB수량/클릭) | K18: DB단가 (광고비/DB수량) | L18: 미팅전환 건수 | M18: 미팅전환률 (미팅건수/DB수량) | N18: 수당 매출 | O18: 클로징 건수 | P18: 비고 (고객이름, 메모 등) | Q18: 클로징률 (클로징건수/DB수량) | R18: 순이익(원) | S18: ROAS (매출/광고비)*100 | T18: ROI (순이익/광고비)*100
A19: 2월 3주 2/15~2/21 (토~금) | B19: 맥스 | G19: =iferror(E19/D19,"") | J19: =iferror(G19/C19,"") | K19: =iferror(H19/I19,"") | M19: =iferror(L19/I19,"") | Q19: =iferror(O19/I19,"") | R19: =iferror(N19-H19,"") -> 0 | S19: =iferror(N19/H19,"") | T19: =iferror(R19/H19,"")
B20: 해리 | F20: =iferror(H20/E20,"") | G20: =iferror(E20/D20,"") | J20: =iferror(G20/C20,"") | K20: =iferror(H20/I20,"") | M20: =iferror(L20/I20,"") | Q20: =iferror(O20/I20,"") | R20: =iferror(N20-H20,"") -> 0 | S20: =iferror(N20/H20,"") | T20: =iferror(R20/H20,"")
B21: 로즈 | F21: =iferror(H21/E21,"") | G21: =iferror(E21/D21,"") | J21: =iferror(I21/E21,"") | K21: =iferror(H21/I21,"") | M21: =iferror(L21/I21,"") | Q21: =iferror(O21/I21,"") | R21: =iferror(N21-H21,"") -> 0 | S21: =iferror(N21/H21,"") | T21: =iferror(R21/H21,"")
B22: 페르 | F22: =iferror(H22/E22,"") | G22: =iferror(E22/D22,"") | J22: =iferror(G22/C22,"") | K22: =iferror(H22/I22,"") | M22: =iferror(L22/I22,"") | Q22: =iferror(O22/I22,"") | R22: =iferror(N22-H22,"") -> 0 | S22: =iferror(N22/H22,"") | T22: =iferror(R22/H22,"")
A23: 팀평균 | F23: =averageif(F19:F22,">0") -> #DIV/0! | G23: =averageif(G19:G22,">0") -> #DIV/0! | I23: =SUM(I19:I22) -> 0 | J23: =averageif(J19:J22,">0") -> #DIV/0! | K23: =averageif(K19:K22,">0") -> #DIV/0! | M23: =averageif(M19:M22,">0") -> #DIV/0! | N23: =SUM(N19:N22) -> 0 | O23: =SUM(O19:O22) -> 0 | Q23: =averageif(Q19:Q22,">0") -> #DIV/0! | S23: =averageif(S19:S22,">0") -> #DIV/0! | T23: =averageif(T19:T22,">0") -> #DIV/0!
B25: 담당자 | C25: 매체분석 | I25: DB효율 | N25: 매출분석
C26: 작성시점 | D26: 노출량 | E26: 클릭 | F26: 클릭당 단가 (원) CPC (광고집행비/클릭) | G26: 클릭률 CTR (클릭/노출량) | H26: 주간 집행 광고비 | I26: DB수량 | J26: DB전환률 (DB수량/클릭) | K26: DB단가 (광고비/DB수량) | L26: 미팅전환 건수 | M26: 미팅전환률 (미팅건수/DB수량) | N26: 수당 매출 | O26: 클로징 건수 | P26: 비고 (고객이름, 메모 등) | Q26: 클로징률 (클로징건수/DB수량) | R26: 순이익(원) | S26: ROAS (매출/광고비)*100 | T26: ROI (순이익/광고비)*100
A27: 2월 4주 2/22~2/28 (토~화) | B27: 맥스 | G27: =iferror(E27/D27,"") | J27: =iferror(G27/C27,"") | K27: =iferror(H27/I27,"") | M27: =iferror(L27/I27,"") | Q27: =iferror(O27/I27,"") | R27: =iferror(N27-H27,"") -> 0 | S27: =iferror(N27/H27,"") | T27: =iferror(R27/H27,"")
B28: 해리 | F28: =iferror(H28/E28,"") | G28: =iferror(E28/D28,"") | J28: =iferror(G28/C28,"") | K28: =iferror(H28/I28,"") | M28: =iferror(L28/I28,"") | Q28: =iferror(O28/I28,"") | R28: =iferror(N28-H28,"") -> 0 | S28: =iferror(N28/H28,"") | T28: =iferror(R28/H28,"")
B29: 로즈 | F29: =iferror(H29/E29,"") | G29: =iferror(E29/D29,"") | J29: =iferror(I29/E29,"") | K29: =iferror(H29/I29,"") | M29: =iferror(L29/I29,"") | Q29: =iferror(O29/I29,"") | R29: =iferror(N29-H29,"") -> 0 | S29: =iferror(N29/H29,"") | T29: =iferror(R29/H29,"")
B30: 페르 | F30: =iferror(H30/E30,"") | G30: =iferror(E30/D30,"") | J30: =iferror(G30/C30,"") | K30: =iferror(H30/I30,"") | M30: =iferror(L30/I30,"") | Q30: =iferror(O30/I30,"") | R30: =iferror(N30-H30,"") -> 0 | S30: =iferror(N30/H30,"") | T30: =iferror(R30/H30,"")
A31: 팀평균 | F31: =averageif(F27:F30,">0") -> #DIV/0! | G31: =averageif(G27:G30,">0") -> #DIV/0! | I31: =SUM(I27:I30) -> 0 | J31: =averageif(J27:J30,">0") -> #DIV/0! | K31: =averageif(K27:K30,">0") -> #DIV/0! | M31: =averageif(M27:M30,">0") -> #DIV/0! | N31: =SUM(N27:N30) -> 0 | O31: =SUM(O27:O30) -> 0 | Q31: =averageif(Q27:Q30,">0") -> #DIV/0! | S31: =averageif(S27:S30,">0") -> #DIV/0! | T31: =averageif(T27:T30,">0") -> #DIV/0!
A34: 2월 | B34: 담당자 | C34: 매체분석 | I34: DB효율 | N34: 매출분석
C35: 작성시점 | D35: 노출량 | E35: 클릭 | F35: 클릭당 단가 (원) CPC (광고집행비/클릭) | G35: 클릭률 CTR (클릭/노출량) | H35: 월간 집행 광고비 | I35: DB수량 | J35: DB전환률 (DB수량/클릭) | K35: DB단가 (광고비/DB수량) | L35: 미팅전환 건수 | M35: 미팅전환률 (미팅건수/DB수량) | N35: 수당 매출 | O35: 클로징 건수 | P35: 비고 (고객이름, 메모 등) | Q35: 클로징률 (클로징건수/DB수량) | R35: 순이익(원) | S35: ROAS (매출/광고비)*100 | T35: ROI (순이익/광고비)*100
A36: 1월 통계 | B36: 맥스 | D36: =D3+D11+D19+D27 -> 0 | E36: =E3+E11+E19+E27 -> 0 | F36: =iferror(H36/E36,"") | G36: =iferror(E36/D36,"") | H36: =H3+H11+H19+H27 -> 0 | I36: =I3+I11+I19+I27 -> 0 | J36: =iferror(F36/B36,"") | K36: =iferror(E36/F36,"") | L36: =L3+L11+L19+L27 -> 0 | M36: =iferror(I36/E36,"") | N36: =N3+N11+N19+N27 -> 0 | O36: =O3+O11+O19+O27 -> 0 | Q36: =iferror(O36/I36,"") | R36: =iferror(N36-H36,"") -> 0 | S36: =iferror(N36/H36,"") | T36: =iferror(R36/H36,"")
B37: 해리 | D37: =D4+D12+D20+D28 -> 0 | E37: =E4+E12+E20+E28 -> 0 | F37: =iferror(H37/E37,"") | G37: =iferror(E37/D37,"") | H37: =H4+H12+H20+H28 -> 0 | I37: =I4+I12+I20+I28 -> 0 | J37: =iferror(F37/B37,"") | K37: =iferror(H37/I37,"") | L37: =L4+L12+L20+L28 -> 0 | M37: =iferror(I37/E37,"") | N37: =N4+N12+N20+N28 -> 600000 | O37: =O4+O12+O20+O28 -> 3 | Q37: =iferror(O37/I37,"") | R37: =iferror(N37-H37,"") -> 600000 | S37: =iferror(N37/H37,"") | T37: =iferror(R37/H37,"")
B38: 로즈 | D38: =D5+D13+D21+D29 -> 0 | E38: =E5+E13+E21+E29 -> 0 | F38: =iferror(H38/E38,"") | G38: =iferror(E38/D38,"") | H38: =H5+H13+H21+H29 -> 0 | I38: =I5+I13+I21+I29 -> 0 | J38: =iferror(I38/E38,"") | K38: =iferror(H38/I38,"") | L38: =L5+L13+L21+L29 -> 0 | M38: =iferror(I38/E38,"") | N38: =N5+N13+N21+N29 -> 0 | O38: =O5+O13+O21+O29 -> 0 | Q38: =iferror(O38/I38,"") | R38: =iferror(N38-H38,"") -> 0 | S38: =iferror(N38/H38,"") | T38: =iferror(R38/H38,"")
B39: 페르 | D39: =D6+D14+D22+D30 -> 0 | E39: =E6+E14+E22+E30 -> 0 | F39: =iferror(H39/E39,"") | G39: =iferror(E39/D39,"") | H39: =H6+H14+H22+H30 -> 0 | I39: =I6+I14+I22+I30 -> 0 | J39: =iferror(I39/E39,"") | K39: =iferror(E39/F39,"") | L39: =L6+L14+L22+L30 -> 0 | M39: =iferror(I39/E39,"") | N39: =N6+N14+N22+N30 -> 0 | O39: =O6+O14+O22+O30 -> 0 | Q39: =iferror(O39/I39,"") | R39: =iferror(N39-H39,"") -> 0 | S39: =iferror(N39/H39,"") | T39: =iferror(R39/H39,"")
A40: 팀평균 | F40: =averageif(F36:F39,">0") -> #DIV/0! | G40: =averageif(G36:G39,">0") -> #DIV/0! | I40: =SUM(I36:I39) -> 0 | K40: =averageif(K36:K39,">0") -> #DIV/0! | M40: =averageif(M36:M39,">0") -> #DIV/0! | N40: =SUM(N36:N39) -> 600000 | O40: =SUM(O36:O39) -> 3 | Q40: =averageif(Q36:Q39,">0") -> #DIV/0! | S40: =averageif(S36:S39,">0") -> #DIV/0! | T40: =averageif(T36:T39,">0") -> #DIV/0!
A42: B2B 총계 | B42: 담당자 | C42: 매체분석 | I42: DB효율 | N42: 매출분석
C43: 작성시점 | D43: 노출량 | E43: 클릭 | F43: 클릭당 단가 (원) CPC (광고집행비/클릭) | G43: 클릭률 CTR (클릭/노출량) | H43: 월간 집행 광고비 | I43: DB수량 | J43: DB전환률 (DB수량/클릭) | K43: DB단가 (광고비/DB수량) | L43: 미팅전환 건수 | M43: 미팅전환률 (미팅건수/DB수량) | N43: 수당 매출 | O43: 클로징 건수 | P43: 비고 (고객이름, 메모 등) | Q43: 클로징률 (클로징건수/DB수량) | R43: 순이익(원) | S43: ROAS (매출/광고비)*100 | T43: ROI (순이익/광고비)*100
A44: 12~2월 | B44: 맥스 | D44: =D36+'1월'!D51 -> 0 | E44: =E36+'1월'!E51 -> 0 | F44: =iferror(H44/E44,"") | G44: =iferror(E44/D44,"") | H44: =H36+'1월'!H51 -> 0 | I44: =I36+'1월'!I51 -> 0 | J44: =iferror(F44/B44,"") | K44: =iferror(E44/F44,"") | L44: =L36+'1월'!L51 -> 0 | M44: =iferror(I44/E44,"") | N44: =N36+'1월'!N51 -> 0 | O44: =O36+'1월'!O51 -> 0 | Q44: =iferror(O44/I44,"") | R44: =iferror(N44-H44,"") -> 0 | S44: =iferror(N44/H44,"") | T44: =iferror(R44/H44,"")
B45: 해리 | D45: =D37+'1월'!D52 -> 8591 | E45: =E37+'1월'!E52 -> 397 | F45: =iferror(H45/E45,"") -> 695.0529 | G45: =iferror(E45/D45,"") -> 0.046211151 | H45: =H37+'1월'!H52 -> 275936 | I45: =I37+'1월'!I52 -> 125 | J45: =iferror(F45/B45,"") | K45: =iferror(H45/I45,"") -> 2207.488 | L45: =L37+'1월'!L52 -> 30 | M45: =iferror(I45/E45,"") -> 0.31486146 | N45: =N37+'1월'!N52 -> 2960000 | O45: =O37+'1월'!O52 -> 7 | Q45: =iferror(O45/I45,"") -> 0.056 | R45: =iferror(N45-H45,"") -> 2684064 | S45: =iferror(N45/H45,"") -> 10.727125 | T45: =iferror(R45/H45,"") -> 9.7271251
B46: 로즈 | D46: =D38+'1월'!D53 -> 30001 | E46: =E38+'1월'!E53 -> 1612 | F46: =iferror(H46/E46,"") -> 496.75558 | G46: =iferror(E46/D46,"") -> 0.053731542 | H46: =H38+'1월'!H53 -> 800770 | I46: =I38+'1월'!I53 -> 183 | J46: =iferror(I46/E46,"") -> 0.11352357 | K46: =iferror(H46/I46,"") -> 4375.7923 | L46: =L38+'1월'!L53 -> 8 | M46: =iferror(I46/E46,"") -> 0.11352357 | N46: =N38+'1월'!N53 -> 880000 | O46: =O38+'1월'!O53 -> 1 | Q46: =iferror(O46/I46,"") -> 0.0054644809 | R46: =iferror(N46-H46,"") -> 79230 | S46: =iferror(N46/H46,"") -> 1.0989423 | T46: =iferror(R46/H46,"") -> 0.098942268
...

Sheet 1월
A1: 1월 | B1: 담당자 | C1: 매체분석 | I1: DB효율 | N1: 매출분석
C2: 작성시점 | D2: 노출량 | E2: 클릭 | F2: 클릭당 단가 (원) CPC (광고집행비/클릭) | G2: 클릭률 CTR (클릭/노출량) | H2: 주간 집행 광고비 | I2: DB수량 | J2: DB전환률 (DB수량/클릭) | K2: DB단가 (광고비/DB수량) | L2: 미팅전환 건수 | M2: 미팅전환률 (미팅건수/DB수량) | N2: 수당 매출 | O2: 클로징 건수 | P2: 비고 (고객이름, 아카데미 종류 등) | Q2: 클로징률 (클로징건수/DB수량) | R2: 순이익(원) | S2: ROAS (매출/광고비)*100 | T2: ROI (순이익/광고비)*100
A3: 1월 1주 1/1~1/3 (수~금) | B3: 맥스 | F3: =iferror(H3/E3,"") | G3: =iferror(E3/D3,"") | J3: =iferror(G3/C3,"") | K3: =iferror(H3/I3,"") | M3: =iferror(L3/I3,"") | Q3: =iferror(O3/I3,"") | R3: =iferror(N3-H3,"") -> 0 | S3: =iferror(N3/H3,"") | T3: =iferror(R3/H3,"")
B4: 해리 | F4: =iferror(H4/E4,"") | G4: =iferror(E4/D4,"") | J4: =iferror(G4/C4,"") | K4: =iferror(H4/I4,"") | M4: =iferror(L4/I4,"") | Q4: =iferror(O4/I4,"") | R4: =iferror(N4-H4,"") -> 0 | S4: =iferror(N4/H4,"") | T4: =iferror(R4/H4,"")
B5: 로즈 | C5: 45660 | D5: 1350 | E5: 86 | F5: =iferror(H5/E5,"") -> 376.46512 | G5: =iferror(E5/D5,"") -> 0.063703704 | H5: 32376 | I5: 9 | J5: =iferror(I5/E5,"") -> 0.10465116 | K5: =iferror(H5/I5,"") -> 3597.3333 | M5: =iferror(L5/I5,"") -> 0
B6: 페르 | F6: =iferror(H6/E6,"") | G6: =iferror(E6/D6,"") | J6: =iferror(G6/C6,"") | K6: =iferror(H6/I6,"") | M6: =iferror(L6/I6,"")
A7: 팀평균 | F7: =averageif(F3:F6,">0") -> 376.46512 | G7: =averageif(G3:G6,">0") -> 0.063703704 | I7: =SUM(I3:I6) -> 9 | J7: =averageif(J3:J6,">0") -> 0.10465116 | K7: =averageif(K3:K6,">0") -> 3597.3333 | M7: =averageif(M3:M6,">0") -> #DIV/0! | N7: =SUM(N3:N6) -> 0 | O7: =SUM(O3:O6) -> 0 | Q7: =averageif(Q3:Q6,">0") -> #DIV/0! | S7: =averageif(S3:S6,">0") -> #DIV/0! | T7: =averageif(T3:T6,">0") -> #DIV/0!
B9: 담당자 | C9: 매체분석 | I9: DB효율 | N9: 매출분석
C10: 작성시점 | D10: 노출량 | E10: 클릭 | F10: 클릭당 단가 (원) CPC (광고집행비/클릭) | G10: 클릭률 CTR (클릭/노출량) | H10: 주간 집행 광고비 | I10: DB수량 | J10: DB전환률 (DB수량/클릭) | K10: DB단가 (광고비/DB수량) | L10: 미팅전환 건수 | M10: 미팅전환률 (미팅건수/DB수량) | N10: 수당 매출 | O10: 클로징 건수 | P10: 비고 (고객이름, 메모 등) | Q10: 클로징률 (클로징건수/DB수량) | R10: 순이익(원) | S10: ROAS (매출/광고비)*100 | T10: ROI (순이익/광고비)*100
A11: 1월 2주 1/4~1/10 (토~금) | B11: 맥스 | G11: =iferror(E11/D11,"") | J11: =iferror(G11/C11,"") | K11: =iferror(H11/I11,"") | M11: =iferror(L11/I11,"") | Q11: =iferror(O11/I11,"") | R11: =iferror(N11-H11,"") -> 0 | S11: =iferror(N11/H11,"") | T11: =iferror(R11/H11,"")
B12: 해리 | F12: =iferror(H12/E12,"") | G12: =iferror(E12/D12,"") | J12: =iferror(I12/E12,"") | K12: =iferror(H12/I12,"") | M12: =iferror(L12/I12,"") | Q12: =iferror(O12/I12,"") | R12: =iferror(N12-H12,"") -> 0 | S12: =iferror(N12/H12,"") | T12: =iferror(R12/H12,"")
B13: 로즈 | C13: ~1/10 | D13: 4500 | E13: 242 | F13: =iferror(H13/E13,"") -> 480.50826 | G13: =iferror(E13/D13,"") -> 0.053777778 | H13: 116283 | I13: 20 | J13: =iferror(I13/E13,"") -> 0.082644628 | K13: =iferror(H13/I13,"") -> 5814.15 | M13: =iferror(L13/I13,"") -> 0 | Q13: =iferror(O13/I13,"") -> 0 | R13: =iferror(N13-H13,"") -> -116283 | S13: =iferror(N13/H13,"") -> 0 | T13: =iferror(R13/H13,"") -> -1
B14: 페르 | F14: =iferror(H14/E14,"") | G14: =iferror(E14/D14,"") | J14: =iferror(G14/C14,"") | K14: =iferror(H14/I14,"") | M14: =iferror(L14/I14,"") | Q14: =iferror(O14/I14,"") | R14: =iferror(N14-H14,"") -> 0 | S14: =iferror(N14/H14,"") | T14: =iferror(R14/H14,"")
A15: 팀평균 | F15: =averageif(F11:F14,">0") -> 480.50826 | G15: =averageif(G11:G14,">0") -> 0.053777778 | I15: =SUM(I11:I14) -> 20 | J15: =averageif(J11:J14,">0") -> 0.082644628 | K15: =averageif(K11:K14,">0") -> 5814.15 | M15: =averageif(M11:M14,">0") -> #DIV/0! | N15: =SUM(N11:N14) -> 0 | O15: =SUM(O11:O14) -> 0 | Q15: =averageif(Q11:Q14,">0") -> #DIV/0! | S15: =averageif(S11:S14,">0") -> #DIV/0! | T15: =averageif(T11:T14,">0") -> #DIV/0!
B17: 담당자 | C17: 매체분석 | I17: DB효율 | N17: 매출분석
C18: 작성시점 | D18: 노출량 | E18: 클릭 | F18: 클릭당 단가 (원) CPC (광고집행비/클릭) | G18: 클릭률 CTR (클릭/노출량) | H18: 주간 집행 광고비 | I18: DB수량 | J18: DB전환률 (DB수량/클릭) | K18: DB단가 (광고비/DB수량) | L18: 미팅전환 건수 | M18: 미팅전환률 (미팅건수/DB수량) | N18: 수당 매출 | O18: 클로징 건수 | P18: 비고 (고객이름, 메모 등) | Q18: 클로징률 (클로징건수/DB수량) | R18: 순이익(원) | S18: ROAS (매출/광고비)*100 | T18: ROI (순이익/광고비)*100
A19: 1월 3주 1/11~1/17 (토~금) | B19: 맥스 | G19: =iferror(E19/D19,"") | J19: =iferror(G19/C19,"") | K19: =iferror(H19/I19,"") | M19: =iferror(L19/I19,"") | Q19: =iferror(O19/I19,"") | R19: =iferror(N19-H19,"") -> 0 | S19: =iferror(N19/H19,"") | T19: =iferror(R19/H19,"")
B20: 해리 | F20: =iferror(H20/E20,"") | G20: =iferror(E20/D20,"") | J20: =iferror(G20/C20,"") | K20: =iferror(H20/I20,"") | M20: =iferror(L20/I20,"") | Q20: =iferror(O20/I20,"") | R20: =iferror(N20-H20,"") -> 0 | S20: =iferror(N20/H20,"") | T20: =iferror(R20/H20,"")
B21: 로즈 | C21: ~1/17 | D21: 2722 | E21: 133 | F21: =iferror(H21/E21,"") -> 626.15789 | G21: =iferror(E21/D21,"") -> 0.048861132 | H21: 83279 | I21: 15 | J21: =iferror(I21/E21,"") -> 0.11278195 | K21: =iferror(H21/I21,"") -> 5551.9333 | M21: =iferror(L21/I21,"") -> 0 | Q21: =iferror(O21/I21,"") -> 0 | R21: =iferror(N21-H21,"") -> -83279 | S21: =iferror(N21/H21,"") -> 0 | T21: =iferror(R21/H21,"") -> -1
B22: 페르 | F22: =iferror(H22/E22,"") | G22: =iferror(E22/D22,"") | J22: =iferror(G22/C22,"") | K22: =iferror(H22/I22,"") | M22: =iferror(L22/I22,"") | Q22: =iferror(O22/I22,"") | R22: =iferror(N22-H22,"") -> 0 | S22: =iferror(N22/H22,"") | T22: =iferror(R22/H22,"")
A23: 팀평균 | F23: =averageif(F19:F22,">0") -> 626.15789 | G23: =averageif(G19:G22,">0") -> 0.048861132 | I23: =SUM(I19:I22) -> 15 | J23: =averageif(J19:J22,">0") -> 0.11278195 | K23: =averageif(K19:K22,">0") -> 5551.9333 | M23: =averageif(M19:M22,">0") -> #DIV/0! | N23: =SUM(N19:N22) -> 0 | O23: =SUM(O19:O22) -> 0 | Q23: =averageif(Q19:Q22,">0") -> #DIV/0! | S23: =averageif(S19:S22,">0") -> #DIV/0! | T23: =averageif(T19:T22,">0") -> #DIV/0!
B25: 담당자 | C25: 매체분석 | I25: DB효율 | N25: 매출분석
C26: 작성시점 | D26: 노출량 | E26: 클릭 | F26: 클릭당 단가 (원) CPC (광고집행비/클릭) | G26: 클릭률 CTR (클릭/노출량) | H26: 주간 집행 광고비 | I26: DB수량 | J26: DB전환률 (DB수량/클릭) | K26: DB단가 (광고비/DB수량) | L26: 미팅전환 건수 | M26: 미팅전환률 (미팅건수/DB수량) | N26: 수당 매출 | O26: 클로징 건수 | P26: 비고 (고객이름, 메모 등) | Q26: 클로징률 (클로징건수/DB수량) | R26: 순이익(원) | S26: ROAS (매출/광고비)*100 | T26: ROI (순이익/광고비)*100
A27: 1월 4주 1/18~1/24 (토~화) | B27: 맥스 | G27: =iferror(E27/D27,"") | J27: =iferror(G27/C27,"") | K27: =iferror(H27/I27,"") | M27: =iferror(L27/I27,"") | Q27: =iferror(O27/I27,"") | R27: =iferror(N27-H27,"") -> 0 | S27: =iferror(N27/H27,"") | T27: =iferror(R27/H27,"")
B28: 해리 | F28: =iferror(H28/E28,"") | G28: =iferror(E28/D28,"") | J28: =iferror(G28/C28,"") | K28: =iferror(H28/I28,"") | M28: =iferror(L28/I28,"") | Q28: =iferror(O28/I28,"") | R28: =iferror(N28-H28,"") -> 0 | S28: =iferror(N28/H28,"") | T28: =iferror(R28/H28,"")
B29: 로즈 | C29: ~1/24 | D29: 3663 | E29: 165 | F29: =iferror(H29/E29,"") -> 509.98182 | G29: =iferror(E29/D29,"") -> 0.045045045 | H29: 84147 | I29: 17 | J29: =iferror(I29/E29,"") -> 0.1030303 | K29: =iferror(H29/I29,"") -> 4949.8235 | M29: =iferror(L29/I29,"") -> 0 | Q29: =iferror(O29/I29,"") -> 0 | R29: =iferror(N29-H29,"") -> -84147 | S29: =iferror(N29/H29,"") -> 0 | T29: =iferror(R29/H29,"") -> -1
B30: 페르 | F30: =iferror(H30/E30,"") | G30: =iferror(E30/D30,"") | J30: =iferror(G30/C30,"") | K30: =iferror(H30/I30,"") | M30: =iferror(L30/I30,"") | Q30: =iferror(O30/I30,"") | R30: =iferror(N30-H30,"") -> 0 | S30: =iferror(N30/H30,"") | T30: =iferror(R30/H30,"")
A31: 팀평균 | F31: =averageif(F27:F30,">0") -> 509.98182 | G31: =averageif(G27:G30,">0") -> 0.045045045 | I31: =SUM(I27:I30) -> 17 | J31: =averageif(J27:J30,">0") -> 0.1030303 | K31: =averageif(K27:K30,">0") -> 4949.8235 | M31: =averageif(M27:M30,">0") -> #DIV/0! | N31: =SUM(N27:N30) -> 0 | O31: =SUM(O27:O30) -> 0 | Q31: =averageif(Q27:Q30,">0") -> #DIV/0! | S31: =averageif(S27:S30,">0") -> #DIV/0! | T31: =averageif(T27:T30,">0") -> #DIV/0!
B33: 담당자 | C33: 매체분석 | I33: DB효율 | N33: 매출분석
C34: 작성시점 | D34: 노출량 | E34: 클릭 | F34: 클릭당 단가 (원) CPC (광고집행비/클릭) | G34: 클릭률 CTR (클릭/노출량) | H34: 주간 집행 광고비 | I34: DB수량 | J34: DB전환률 (DB수량/클릭) | K34: DB단가 (광고비/DB수량) | L34: 미팅전환 건수 | M34: 미팅전환률 (미팅건수/DB수량) | N34: 수당 매출 | O34: 클로징 건수 | P34: 비고 (고객이름, 메모 등) | Q34: 클로징률 (클로징건수/DB수량) | R34: 순이익(원) | S34: ROAS (매출/광고비)*100 | T34: ROI (순이익/광고비)*100
A35: 1월 5주 1/25~1/31 (토~화) | B35: 맥스 | G35: =iferror(E35/D35,"") | J35: =iferror(G35/C35,"") | K35: =iferror(H35/I35,"") | M35: =iferror(L35/I35,"") | Q35: =iferror(O35/I35,"") | R35: =iferror(N35-H35,"") -> 0 | S35: =iferror(N35/H35,"") | T35: =iferror(R35/H35,"")
B36: 해리 | F36: =iferror(H36/E36,"") | G36: =iferror(E36/D36,"") | J36: =iferror(G36/C36,"") | K36: =iferror(H36/I36,"") | M36: =iferror(L36/I36,"") | Q36: =iferror(O36/I36,"") | R36: =iferror(N36-H36,"") -> 0 | S36: =iferror(N36/H36,"") | T36: =iferror(R36/H36,"")
B37: 로즈 | C37: 45687 | D37: 3260 | E37: 207 | F37: =iferror(H37/E37,"") -> 454.10628 | G37: =iferror(E37/D37,"") -> 0.063496933 | H37: 94000 | I37: 21 | J37: =iferror(I37/E37,"") -> 0.10144928 | K37: =iferror(H37/I37,"") -> 4476.1905 | M37: =iferror(L37/I37,"") -> 0 | Q37: =iferror(O37/I37,"") -> 0 | R37: =iferror(N37-H37,"") -> -94000 | S37: =iferror(N37/H37,"") -> 0 | T37: =iferror(R37/H37,"") -> -1
B38: 페르 | F38: =iferror(H38/E38,"") | G38: =iferror(E38/D38,"") | J38: =iferror(G38/C38,"") | K38: =iferror(H38/I38,"") | M38: =iferror(L38/I38,"") | Q38: =iferror(O38/I38,"") | R38: =iferror(N38-H38,"") -> 0 | S38: =iferror(N38/H38,"") | T38: =iferror(R38/H38,"")
A39: 팀평균 | F39: =averageif(F35:F38,">0") -> 454.10628 | G39: =averageif(G35:G38,">0") -> 0.063496933 | I39: =SUM(I35:I38) -> 21 | J39: =averageif(J35:J38,">0") -> 0.10144928 | K39: =averageif(K35:K38,">0") -> 4476.1905 | M39: =averageif(M35:M38,">0") -> #DIV/0! | N39: =SUM(N35:N38) -> 0 | O39: =SUM(O35:O38) -> 0 | Q39: =averageif(Q35:Q38,">0") -> #DIV/0! | S39: =averageif(S35:S38,">0") -> #DIV/0! | T39: =averageif(T35:T38,">0") -> #DIV/0!
A41: 1월 | B41: 담당자 | C41: 매체분석 | I41: DB효율 | N41: 매출분석
C42: 작성시점 | D42: 노출량 | E42: 클릭 | F42: 클릭당 단가 (원) CPC (광고집행비/클릭) | G42: 클릭률 CTR (클릭/노출량) | H42: 월간 집행 광고비 | I42: DB수량 | J42: DB전환률 (DB수량/클릭) | K42: DB단가 (광고비/DB수량) | L42: 미팅전환 건수 | M42: 미팅전환률 (미팅건수/DB수량) | N42: 수당 매출 | O42: 클로징 건수 | P42: 비고 (고객이름, 메모 등) | Q42: 클로징률 (클로징건수/DB수량) | R42: 순이익(원) | S42: ROAS (매출/광고비)*100 | T42: ROI (순이익/광고비)*100
A43: 1월 통계 | B43: 맥스 | D43: =D3+D11+D19+D27+D35 -> 0 | E43: =E3+E11+E19+E27+E35 -> 0 | F43: =iferror(H43/E43,"") | G43: =iferror(E43/D43,"") | H43: =H3+H11+H19+H27+H35 -> 0 | I43: =I3+I11+I19+I27+I35 -> 0 | J43: =iferror(F43/B43,"") | K43: =iferror(E43/F43,"") | L43: =L3+L11+L19+L27+L35 -> 0 | M43: =iferror(I43/E43,"") | N43: =N3+N11+N19+N27+N35 -> 0 | O43: =O3+O11+O19+O27+O35 -> 0 | Q43: =iferror(O43/I43,"") | R43: =iferror(N43-H43,"") -> 0 | S43: =iferror(N43/H43,"") | T43: =iferror(R43/H43,"")
B44: 해리 | D44: =D4+D12+D20+D28+D36 -> 0 | E44: =E4+E12+E20+E28+E36 -> 0 | F44: =iferror(H44/E44,"") | G44: =iferror(E44/D44,"") | H44: =H4+H12+H20+H28+H36 -> 0 | I44: =I4+I12+I20+I28+I36 -> 0 | J44: =iferror(F44/B44,"") | K44: =iferror(H44/I44,"") | L44: =L4+L12+L20+L28+L36 -> 0 | M44: =iferror(I44/E44,"") | N44: =N4+N12+N20+N28+N36 -> 0 | O44: =O4+O12+O20+O28+O36 -> 0 | Q44: =iferror(O44/I44,"") | R44: =iferror(N44-H44,"") -> 0 | S44: =iferror(N44/H44,"") | T44: =iferror(R44/H44,"")
B45: 로즈 | D45: =D5+D13+D21+D29+D37 -> 15495 | E45: =E5+E13+E21+E29+E37 -> 833 | F45: =iferror(H45/E45,"") -> 519.29532 | G45: =iferror(E45/D45,"") -> 0.053759277 | H45: 432573 | I45: =I5+I13+I21+I29+I37 -> 82 | J45: =iferror(I45/E45,"") -> 0.098439376 | K45: =iferror(H45/I45,"") -> 5275.2805 | L45: =L5+L13+L21+L29+L37 -> 0 | M45: =iferror(I45/E45,"") -> 0.098439376 | N45: =N5+N13+N21+N29+N37 -> 0 | O45: =O5+O13+O21+O29+O37 -> 0 | Q45: =iferror(O45/I45,"") -> 0 | R45: =iferror(N45-H45,"") -> -432573 | S45: =iferror(N45/H45,"") -> 0 | T45: =iferror(R45/H45,"") -> -1
...

Sheet 12월(B2B)
A1: 12월 | B1: 담당자 | C1: 매체분석 | I1: DB효율 | N1: 매출분석
C2: 작성시점 | D2: 노출량 | E2: 클릭 | F2: 클릭당 단가 (원) CPC (광고집행비/클릭) | G2: 클릭률 CTR (클릭/노출량) | H2: 주간 집행 광고비 | I2: DB수량 | J2: DB전환률 (DB수량/클릭) | K2: DB단가 (광고비/DB수량) | L2: 미팅전환 건수 | M2: 미팅전환률 (미팅건수/DB수량) | N2: 수당 매출 | O2: 클로징 건수 | P2: 비고 (고객이름, 아카데미 종류 등) | Q2: 클로징률 (클로징건수/DB수량) | R2: 순이익(원) | S2: ROAS (매출/광고비)*100 | T2: ROI (순이익/광고비)*100
A3: 12월 1주 11/30~12/6 (토~금) | B3: 맥스 | F3: =iferror(H3/E3,"") | G3: =iferror(E3/D3,"") | J3: =iferror(G3/C3,"") | K3: =iferror(H3/I3,"") | M3: =iferror(L3/I3,"") | Q3: =iferror(O3/I3,"") | R3: =iferror(N3-H3,"") -> 0 | S3: =iferror(N3/H3,"") | T3: =iferror(R3/H3,"")
B4: 해리 | C4: 10/22~12/6 | D4: 4733 | E4: 248 | F4: =iferror(H4/E4,"") -> 809.11694 | G4: =iferror(E4/D4,"") -> 0.052398056 | H4: 200661 | I4: 112 | J4: =iferror(I4/E4,"") -> 0.4516129 | K4: =iferror(H4/I4,"") -> 1791.6161 | L4: 25 | M4: =iferror(L4/I4,"") -> 0.22321429 | N4: 1480000 | O4: 3 | P4: 오월,주민규,김사무엘 | Q4: =iferror(O4/I4,"") -> 0.026785714 | R4: =iferror(N4-H4,"") -> 1279339 | S4: =iferror(N4/H4,"") -> 7.3756236 | T4: =iferror(R4/H4,"") -> 6.3756236
B5: 로즈 | C5: 12/6 까지 | D5: 1555 | E5: 86 | F5: =iferror(H5/E5,"") -> 770.03488 | G5: =iferror(E5/D5,"") -> 0.055305466 | H5: 66223 | I5: 10 | J5: =iferror(I5/E5,"") -> 0.11627907 | K5: =iferror(H5/I5,"") -> 6622.3 | L5: 1 | M5: =iferror(L5/I5,"") -> 0.1 | Q5: =iferror(O5/I5,"") -> 0 | R5: =iferror(N5-H5,"") -> -66223 | S5: =iferror(N5/H5,"") -> 0 | T5: =iferror(R5/H5,"") -> -1
B6: 페르 | F6: =iferror(H6/E6,"") | G6: =iferror(E6/D6,"") | J6: =iferror(G6/C6,"") | K6: =iferror(H6/I6,"") | M6: =iferror(L6/I6,"") | Q6: =iferror(O6/I6,"") | R6: =iferror(N6-H6,"") -> 0 | S6: =iferror(N6/H6,"") | T6: =iferror(R6/H6,"")
A7: 팀평균 | F7: =averageif(F3:F6,">0") -> 789.57591 | G7: =averageif(G3:G6,">0") -> 0.053851761 | I7: =SUM(I3:I6) -> 122 | J7: =averageif(J3:J6,">0") -> 0.28394599 | K7: =averageif(K3:K6,">0") -> 4206.958 | M7: =averageif(M3:M6,">0") -> 0.16160714 | N7: =SUM(N3:N6) -> 1480000 | O7: =SUM(O3:O6) -> 3 | Q7: =averageif(Q3:Q6,">0") -> 0.026785714 | S7: =averageif(S3:S6,">0") -> 7.3756236 | T7: =averageif(T3:T6,">0") -> 6.3756236
B9: 담당자 | C9: 매체분석 | I9: DB효율 | N9: 매출분석
C10: 작성시점 | D10: 노출량 | E10: 클릭 | F10: 클릭당 단가 (원) CPC (광고집행비/클릭) | G10: 클릭률 CTR (클릭/노출량) | H10: 주간 집행 광고비 | I10: DB수량 | J10: DB전환률 (DB수량/클릭) | K10: DB단가 (광고비/DB수량) | L10: 미팅전환 건수 | M10: 미팅전환률 (미팅건수/DB수량) | N10: 수당 매출 | O10: 클로징 건수 | P10: 비고 (고객이름, 메모 등) | Q10: 클로징률 (클로징건수/DB수량) | R10: 순이익(원) | S10: ROAS (매출/광고비)*100 | T10: ROI (순이익/광고비)*100
A11: 12월 2주 12/7~12/13 (토~금) | B11: 맥스 | G11: =iferror(E11/D11,"") | J11: =iferror(G11/C11,"") | K11: =iferror(H11/I11,"") | M11: =iferror(L11/I11,"") | Q11: =iferror(O11/I11,"") | R11: =iferror(N11-H11,"") -> 0 | S11: =iferror(N11/H11,"") | T11: =iferror(R11/H11,"")
B12: 해리 | C12: 12/7~12/12 | D12: 3858 | E12: 149 | F12: =iferror(H12/E12,"") -> 505.20134 | G12: =iferror(E12/D12,"") -> 0.038621047 | H12: 75275 | I12: 13 | J12: =iferror(I12/E12,"") -> 0.087248322 | K12: =iferror(H12/I12,"") -> 5790.3846 | L12: 5 | M12: =iferror(L12/I12,"") -> 0.38461538 | N12: 880000 | O12: 1 | P12: 이호영 | Q12: =iferror(O12/I12,"") -> 0.076923077 | R12: =iferror(N12-H12,"") -> 804725 | S12: =iferror(N12/H12,"") -> 11.690468 | T12: =iferror(R12/H12,"") -> 10.690468
B13: 로즈 | C13: ~12/13 | D13: 5311 | E13: 278 | F13: =iferror(H13/E13,"") -> 501.47842 | G13: =iferror(E13/D13,"") -> 0.052344191 | H13: 139411 | I13: 37 | J13: =iferror(I13/E13,"") -> 0.13309353 | K13: =iferror(H13/I13,"") -> 3767.8649 | L13: 4 | M13: =iferror(L13/I13,"") -> 0.10810811 | P13: 15개 해리, 페르, 맥스에게 이관 | Q13: =iferror(O13/I13,"") -> 0 | R13: =iferror(N13-H13,"") -> -139411 | S13: =iferror(N13/H13,"") -> 0 | T13: =iferror(R13/H13,"") -> -1
B14: 페르 | F14: =iferror(H14/E14,"") | G14: =iferror(E14/D14,"") | J14: =iferror(G14/C14,"") | K14: =iferror(H14/I14,"") | M14: =iferror(L14/I14,"") | Q14: =iferror(O14/I14,"") | R14: =iferror(N14-H14,"") -> 0 | S14: =iferror(N14/H14,"") | T14: =iferror(R14/H14,"")
A15: 팀평균 | F15: =averageif(F11:F14,">0") -> 503.33988 | G15: =averageif(G11:G14,">0") -> 0.045482619 | I15: =SUM(I11:I14) -> 50 | J15: =averageif(J11:J14,">0") -> 0.11017092 | K15: =averageif(K11:K14,">0") -> 4779.1247 | M15: =averageif(M11:M14,">0") -> 0.24636175 | N15: =SUM(N11:N14) -> 880000 | O15: =SUM(O11:O14) -> 1 | Q15: =averageif(Q11:Q14,">0") -> 0.076923077 | S15: =averageif(S11:S14,">0") -> 11.690468 | T15: =averageif(T11:T14,">0") -> 10.690468
B17: 담당자 | C17: 매체분석 | I17: DB효율 | N17: 매출분석
C18: 작성시점 | D18: 노출량 | E18: 클릭 | F18: 클릭당 단가 (원) CPC (광고집행비/클릭) | G18: 클릭률 CTR (클릭/노출량) | H18: 주간 집행 광고비 | I18: DB수량 | J18: DB전환률 (DB수량/클릭) | K18: DB단가 (광고비/DB수량) | L18: 미팅전환 건수 | M18: 미팅전환률 (미팅건수/DB수량) | N18: 수당 매출 | O18: 클로징 건수 | P18: 비고 (고객이름, 메모 등) | Q18: 클로징률 (클로징건수/DB수량) | R18: 순이익(원) | S18: ROAS (매출/광고비)*100 | T18: ROI (순이익/광고비)*100
A19: 12월 3주 12/14~12/20 (토~금) | B19: 맥스 | G19: =iferror(E19/D19,"") | J19: =iferror(G19/C19,"") | K19: =iferror(H19/I19,"") | M19: =iferror(L19/I19,"") | Q19: =iferror(O19/I19,"") | R19: =iferror(N19-H19,"") -> 0 | S19: =iferror(N19/H19,"") | T19: =iferror(R19/H19,"")
B20: 해리 | F20: =iferror(H20/E20,"") | G20: =iferror(E20/D20,"") | J20: =iferror(G20/C20,"") | K20: =iferror(H20/I20,"") | M20: =iferror(L20/I20,"") | Q20: =iferror(O20/I20,"") | R20: =iferror(N20-H20,"") -> 0 | S20: =iferror(N20/H20,"") | T20: =iferror(R20/H20,"")
B21: 로즈 | C21: ~12/20 | D21: 1807 | E21: 111 | F21: =iferror(H21/E21,"") -> 361.97297 | G21: =iferror(E21/D21,"") -> 0.061427781 | H21: 40179 | I21: 10 | J21: =iferror(I21/E21,"") -> 0.09009009 | K21: =iferror(H21/I21,"") -> 4017.9 | L21: 0 | M21: =iferror(L21/I21,"") -> 0 | P21: 10개 해리, 페르, 맥스에게 이관 | Q21: =iferror(O21/I21,"") -> 0 | R21: =iferror(N21-H21,"") -> -40179 | S21: =iferror(N21/H21,"") -> 0 | T21: =iferror(R21/H21,"") -> -1
B22: 페르 | F22: =iferror(H22/E22,"") | G22: =iferror(E22/D22,"") | J22: =iferror(G22/C22,"") | K22: =iferror(H22/I22,"") | M22: =iferror(L22/I22,"") | Q22: =iferror(O22/I22,"") | R22: =iferror(N22-H22,"") -> 0 | S22: =iferror(N22/H22,"") | T22: =iferror(R22/H22,"")
A23: 팀평균 | F23: =averageif(F19:F22,">0") -> 361.97297 | G23: =averageif(G19:G22,">0") -> 0.061427781 | I23: =SUM(I19:I22) -> 10 | J23: =averageif(J19:J22,">0") -> 0.09009009 | K23: =averageif(K19:K22,">0") -> 4017.9 | M23: =averageif(M19:M22,">0") -> #DIV/0! | N23: =SUM(N19:N22) -> 0 | O23: =SUM(O19:O22) -> 0 | Q23: =averageif(Q19:Q22,">0") -> #DIV/0! | S23: =averageif(S19:S22,">0") -> #DIV/0! | T23: =averageif(T19:T22,">0") -> #DIV/0!
B25: 담당자 | C25: 매체분석 | I25: DB효율 | N25: 매출분석
C26: 작성시점 | D26: 노출량 | E26: 클릭 | F26: 클릭당 단가 (원) CPC (광고집행비/클릭) | G26: 클릭률 CTR (클릭/노출량) | H26: 주간 집행 광고비 | I26: DB수량 | J26: DB전환률 (DB수량/클릭) | K26: DB단가 (광고비/DB수량) | L26: 미팅전환 건수 | M26: 미팅전환률 (미팅건수/DB수량) | N26: 수당 매출 | O26: 클로징 건수 | P26: 비고 (고객이름, 메모 등) | Q26: 클로징률 (클로징건수/DB수량) | R26: 순이익(원) | S26: ROAS (매출/광고비)*100 | T26: ROI (순이익/광고비)*100
A27: 12월 4주 12/21~12/31 (토~화) | B27: 맥스 | G27: =iferror(E27/D27,"") | J27: =iferror(G27/C27,"") | K27: =iferror(H27/I27,"") | M27: =iferror(L27/I27,"") | Q27: =iferror(O27/I27,"") | R27: =iferror(N27-H27,"") -> 0 | S27: =iferror(N27/H27,"") | T27: =iferror(R27/H27,"")
B28: 해리 | F28: =iferror(H28/E28,"") | G28: =iferror(E28/D28,"") | J28: =iferror(G28/C28,"") | K28: =iferror(H28/I28,"") | M28: =iferror(L28/I28,"") | Q28: =iferror(O28/I28,"") | R28: =iferror(N28-H28,"") -> 0 | S28: =iferror(N28/H28,"") | T28: =iferror(R28/H28,"")
B29: 로즈 | C29: ~12/31 | D29: 5833 | E29: 304 | F29: =iferror(H29/E29,"") -> 402.57895 | G29: =iferror(E29/D29,"") -> 0.052117264 | H29: 122384 | I29: 44 | J29: =iferror(I29/E29,"") -> 0.14473684 | K29: =iferror(H29/I29,"") -> 2781.4545 | L29: 3 | M29: =iferror(L29/I29,"") -> 0.068181818 | N29: 880000 | O29: 1 | P29: 김베드로 | Q29: =iferror(O29/I29,"") -> 0.022727273 | R29: =iferror(N29-H29,"") -> 757616 | S29: =iferror(N29/H29,"") -> 7.1904824 | T29: =iferror(R29/H29,"") -> 6.1904824
B30: 페르 | F30: =iferror(H30/E30,"") | G30: =iferror(E30/D30,"") | J30: =iferror(G30/C30,"") | K30: =iferror(H30/I30,"") | M30: =iferror(L30/I30,"") | Q30: =iferror(O30/I30,"") | R30: =iferror(N30-H30,"") -> 0 | S30: =iferror(N30/H30,"") | T30: =iferror(R30/H30,"")
A31: 팀평균 | F31: =averageif(F27:F30,">0") -> 402.57895 | G31: =averageif(G27:G30,">0") -> 0.052117264 | I31: =SUM(I27:I30) -> 44 | J31: =averageif(J27:J30,">0") -> 0.14473684 | K31: =averageif(K27:K30,">0") -> 2781.4545 | M31: =averageif(M27:M30,">0") -> 0.068181818 | N31: =SUM(N27:N30) -> 880000 | O31: =SUM(O27:O30) -> 1 | Q31: =averageif(Q27:Q30,">0") -> 0.022727273 | S31: =averageif(S27:S30,">0") -> 7.1904824 | T31: =averageif(T27:T30,">0") -> 6.1904824
A33: 12월 | B33: 담당자 | C33: 매체분석 | I33: DB효율 | N33: 매출분석
C34: 작성시점 | D34: 노출량 | E34: 클릭 | F34: 클릭당 단가 (원) CPC (광고집행비/클릭) | G34: 클릭률 CTR (클릭/노출량) | H34: 월간 집행 광고비 | I34: DB수량 | J34: DB전환률 (DB수량/클릭) | K34: DB단가 (광고비/DB수량) | L34: 미팅전환 건수 | M34: 미팅전환률 (미팅건수/DB수량) | N34: 수당 매출 | O34: 클로징 건수 | P34: 비고 (고객이름, 메모 등) | Q34: 클로징률 (클로징건수/DB수량) | R34: 순이익(원) | S34: ROAS (매출/광고비)*100 | T34: ROI (순이익/광고비)*100
A35: 12월 통계 | B35: 맥스 | D35: =D3+D11+D19+D27 -> 0 | E35: =E3+E11+E19+E27 -> 0 | F35: =iferror(H35/E35,"") | G35: =iferror(E35/D35,"") | H35: =H3+H11+H19+H27 -> 0 | I35: =I3+I11+I19+I27 -> 0 | J35: =iferror(F35/B35,"") | K35: =iferror(E35/F35,"") | L35: =L3+L11+L19+L27 -> 0 | M35: =iferror(I35/E35,"") | N35: =N3+N11+N19+N27 -> 0 | O35: =O3+O11+O19+O27 -> 0 | Q35: =iferror(O35/I35,"") | R35: =iferror(N35-H35,"") -> 0 | S35: =iferror(N35/H35,"") | T35: =iferror(R35/H35,"")
B36: 해리 | D36: =D4+D12+D20+D28 -> 8591 | E36: =E4+E12+E20+E28 -> 397 | F36: =iferror(H36/E36,"") -> 695.0529 | G36: =iferror(E36/D36,"") -> 0.046211151 | H36: =H4+H12+H20+H28 -> 275936 | I36: =I4+I12+I20+I28 -> 125 | J36: =iferror(I36/E36,"") -> 0.31486146 | K36: =iferror(H36/I36,"") -> 2207.488 | L36: =L4+L12+L20+L28 -> 30 | M36: =iferror(I36/E36,"") -> 0.31486146 | N36: =N4+N12+N20+N28 -> 2360000 | O36: =O4+O12+O20+O28 -> 4 | Q36: =iferror(O36/I36,"") -> 0.032 | R36: =iferror(N36-H36,"") -> 2084064 | S36: =iferror(N36/H36,"") -> 8.5527079 | T36: =iferror(R36/H36,"") -> 7.5527079
B37: 로즈 | D37: =D5+D13+D21+D29 -> 14506 | E37: =E5+E13+E21+E29 -> 779 | F37: =iferror(H37/E37,"") -> 472.6534 | G37: =iferror(E37/D37,"") -> 0.053701916 | H37: =H5+H13+H21+H29 -> 368197 | I37: =I5+I13+I21+I29 -> 101 | J37: =iferror(I37/E37,"") -> 0.1296534 | K37: =iferror(H37/I37,"") -> 3645.5149 | L37: =L5+L13+L21+L29 -> 8 | M37: =iferror(I37/E37,"") -> 0.1296534 | N37: =N5+N13+N21+N29 -> 880000 | O37: =O5+O13+O21+O29 -> 1 | Q37: =iferror(O37/I37,"") -> 0.0099009901 | R37: =iferror(N37-H37,"") -> 511803 | S37: =iferror(N37/H37,"") -> 2.3900249 | T37: =iferror(R37/H37,"") -> 1.3900249
B38: 페르 | D38: =D6+D14+D22+D30 -> 0 | E38: =E6+E14+E22+E30 -> 0 | F38: =iferror(H38/E38,"") | G38: =iferror(E38/D38,"") | H38: =H6+H14+H22+H30 -> 0 | I38: =I6+I14+I22+I30 -> 0 | J38: =iferror(F38/B38,"") | K38: =iferror(E38/F38,"") | L38: =L6+L14+L22+L30 -> 0 | M38: =iferror(I38/E38,"") | N38: =N6+N14+N22+N30 -> 0 | O38: =O6+O14+O22+O30 -> 0 | Q38: =iferror(O38/I38,"") | R38: =iferror(N38-H38,"") -> 0 | S38: =iferror(N38/H38,"") | T38: =iferror(R38/H38,"")
A39: 팀평균 | F39: =averageif(F35:F38,">0") -> 583.85315 | G39: =averageif(G35:G38,">0") -> 0.049956534 | I39: =SUM(I35:I38) -> 226 | K39: =averageif(K35:K38,">0") -> 2926.5014 | M39: =averageif(M35:M38,">0") -> 0.22225743 | N39: =SUM(N35:N38) -> 3240000 | O39: =SUM(O35:O38) -> 5 | Q39: =averageif(Q35:Q38,">0") -> 0.020950495 | S39: =averageif(S35:S38,">0") -> 5.4713664 | T39: =averageif(T35:T38,">0") -> 4.4713664

Sheet 11월
A1: 11월 | B1: 담당자 | C1: 매체분석 | I1: DB효율 | L1: 매출분석
C2: 작성시점 | D2: 노출량 | E2: 클릭 | F2: 클릭당 단가 (원) CPC (광고집행비/클릭) | G2: 클릭률 CTR (클릭/노출량) | H2: 주간 집행 광고비 | I2: DB수량 | J2: DB전환률 (DB수량/클릭) | K2: DB단가 (광고비/DB수량) | L2: 수당 매출 | M2: DB 클로징 건수 | N2: 비고 (고객이름, 메모 등) | O2: 판매수량 (객실 수) | P2: 판매수량 (동반 총인원) | Q2: 클로징률 (클로징건수/DB수량) | R2: 순이익(원) | S2: ROAS (매출/광고비)*100 | T2: ROI (순이익/광고비)*100
A3: 11월 1주 11/2~11/8 (토~금) | B3: 맥스 | F3: =iferror(H3/E3,"") | G3: =iferror(E3/D3,"") | J3: =iferror(I3/E3,"") | K3: =iferror(H3/I3,"") | Q3: =iferror(M3/I3,"") | R3: =iferror(L3-H3,"") -> 0 | S3: =iferror(L3/H3,"") | T3: =iferror(R3/H3,"")
B4: 해리 | F4: =iferror(H4/E4,"") | G4: =iferror(E4/D4,"") | J4: =iferror(I4/E4,"") | K4: =iferror(H4/I4,"") | Q4: =iferror(M4/I4,"") | R4: =iferror(L4-H4,"") -> 0 | S4: =iferror(L4/H4,"") | T4: =iferror(R4/H4,"")
B5: 로즈 | F5: =iferror(H5/E5,"") | G5: =iferror(E5/D5,"") | J5: =iferror(I5/E5,"") | K5: =iferror(H5/I5,"") | L5: 160000 | M5: 1 | N5: 박지은(저) | O5: 1 | P5: 2 | Q5: =iferror(M5/I5,"") | R5: =iferror(L5-H5,"") -> 160000 | S5: =iferror(L5/H5,"") | T5: =iferror(R5/H5,"")
B6: 페르 | F6: =iferror(H6/E6,"") | G6: =iferror(E6/D6,"") | J6: =iferror(I6/E6,"") | K6: =iferror(H6/I6,"") | Q6: =iferror(M6/I6,"") | R6: =iferror(L6-H6,"") -> 0 | S6: =iferror(L6/H6,"") | T6: =iferror(R6/H6,"")
A7: 팀평균 | F7: =averageif(F3:F6,">0") -> #DIV/0! | G7: =averageif(G3:G6,">0") -> #DIV/0! | I7: =SUM(I3:I6) -> 0 | J7: =averageif(J3:J6,">0") -> #DIV/0! | K7: =averageif(K3:K6,">0") -> #DIV/0! | L7: =SUM(L3:L6) -> 160000 | M7: =SUM(M3:M6) -> 1 | O7: =SUM(O3:O6) -> 1 | P7: =SUM(P3:P6) -> 2 | Q7: =averageif(Q3:Q6,">0") -> #DIV/0! | S7: =averageif(S3:S6,">0") -> #DIV/0! | T7: =averageif(T3:T6,">0") -> #DIV/0!
B9: 담당자 | C9: 매체분석 | I9: DB효율 | L9: 매출분석
C10: 작성시점 | D10: 노출량 | E10: 클릭 | F10: 클릭당 단가 (원) CPC (광고집행비/클릭) | G10: 클릭률 CTR (클릭/노출량) | H10: 주간 집행 광고비 | I10: DB수량 | J10: DB전환률 (DB수량/클릭) | K10: DB단가 (광고비/DB수량) | L10: 수당 매출 | M10: DB 클로징 건수 | N10: 비고 (고객이름, 메모 등) | O10: 판매수량 (객실 수) | P10: 판매수량 (동반 총인원) | Q10: 클로징률 (클로징건수/DB수량) | R10: 순이익(원) | S10: ROAS (매출/광고비)*100 | T10: ROI (순이익/광고비)*100
A11: 11월 2주 11/9~11/15 (토~금) | B11: 맥스 | G11: =iferror(E11/D11,"") | J11: =iferror(I11/E11,"") | K11: =iferror(H11/I11,"") | L11: 200000 | M11: 1 | N11: 김태복 | Q11: =iferror(M11/I11,"") | R11: =iferror(L11-H11,"") -> 200000 | S11: =iferror(L11/H11,"") | T11: =iferror(R11/H11,"")
B12: 해리 | F12: =iferror(H12/E12,"") | G12: =iferror(E12/D12,"") | J12: =iferror(I12/E12,"") | K12: =iferror(H12/I12,"") | L12: 280000 | M12: 2 | N12: 임진, 윤영준 | O12: 2 | P12: 4 | Q12: =iferror(M12/I12,"") | R12: =iferror(L12-H12,"") -> 280000 | S12: =iferror(L12/H12,"") | T12: =iferror(R12/H12,"")
B13: 로즈 | F13: =iferror(H13/E13,"") | G13: =iferror(E13/D13,"") | J13: =iferror(I13/E13,"") | K13: =iferror(H13/I13,"") | L13: =320000+440000 -> 760000 | M13: 2 | N13: 김영지, 유희진 | O13: 4 | P13: 8 | Q13: =iferror(M13/I13,"") | R13: =iferror(L13-H13,"") -> 760000 | S13: =iferror(L13/H13,"") | T13: =iferror(R13/H13,"")
B14: 페르 | F14: =iferror(H14/E14,"") | G14: =iferror(E14/D14,"") | J14: =iferror(I14/E14,"") | K14: =iferror(H14/I14,"") | Q14: =iferror(M14/I14,"") | R14: =iferror(L14-H14,"") -> 0 | S14: =iferror(L14/H14,"") | T14: =iferror(R14/H14,"")
A15: 팀평균 | F15: =averageif(F11:F14,">0") -> #DIV/0! | G15: =averageif(G11:G14,">0") -> #DIV/0! | I15: =SUM(I11:I14) -> 0 | J15: =averageif(J11:J14,">0") -> #DIV/0! | K15: =averageif(K11:K14,">0") -> #DIV/0! | L15: =SUM(L11:L14) -> 1240000 | M15: =SUM(M11:M14) -> 5 | O15: =SUM(O11:O14) -> 6 | P15: =SUM(P12:P14) -> 12 | Q15: =averageif(Q11:Q14,">0") -> #DIV/0! | S15: =averageif(S11:S14,">0") -> #DIV/0! | T15: =averageif(T11:T14,">0") -> #DIV/0!
B17: 담당자 | C17: 매체분석 | I17: DB효율 | L17: 매출분석
C18: 작성시점 | D18: 노출량 | E18: 클릭 | F18: 클릭당 단가 (원) CPC (광고집행비/클릭) | G18: 클릭률 CTR (클릭/노출량) | H18: 주간 집행 광고비 | I18: DB수량 | J18: DB전환률 (DB수량/클릭) | K18: DB단가 (광고비/DB수량) | L18: 수당 매출 | M18: DB 클로징 건수 | N18: 비고 (고객이름, 메모 등) | O18: 판매수량 (객실 수) | P18: 판매수량 (동반 총인원) | Q18: 클로징률 (클로징건수/DB수량) | R18: 순이익(원) | S18: ROAS (매출/광고비)*100 | T18: ROI (순이익/광고비)*100
A19: 11월 3주 11/16~11/22 (토~금) | B19: 맥스 | G19: =iferror(E19/D19,"") | J19: =iferror(I19/E19,"") | K19: =iferror(H19/I19,"") | Q19: =iferror(M19/I19,"") | R19: =iferror(L19-H19,"") -> 0 | S19: =iferror(L19/H19,"") | T19: =iferror(R19/H19,"")
B20: 해리 | F20: =iferror(H20/E20,"") | G20: =iferror(E20/D20,"") | J20: =iferror(I20/E20,"") | K20: =iferror(H20/I20,"") | Q20: =iferror(M20/I20,"") | R20: =iferror(L20-H20,"") -> 0 | S20: =iferror(L20/H20,"") | T20: =iferror(R20/H20,"")
B21: 로즈 | F21: =iferror(H21/E21,"") | G21: =iferror(E21/D21,"") | J21: =iferror(I21/E21,"") | K21: =iferror(H21/I21,"") | L21: =20000+20000+40000+20000 -> 100000 | N21: 일본관광패키지 (김홍민2, 정춘자2, 김상환4, 박정섭2) | Q21: =iferror(M21/I21,"") | R21: =iferror(L21-H21,"") -> 100000 | S21: =iferror(L21/H21,"") | T21: =iferror(R21/H21,"")
B22: 페르 | F22: =iferror(H22/E22,"") | G22: =iferror(E22/D22,"") | J22: =iferror(I22/E22,"") | K22: =iferror(H22/I22,"") | Q22: =iferror(M22/I22,"") | R22: =iferror(L22-H22,"") -> 0 | S22: =iferror(L22/H22,"") | T22: =iferror(R22/H22,"")
A23: 팀평균 | F23: =averageif(F19:F22,">0") -> #DIV/0! | G23: =averageif(G19:G22,">0") -> #DIV/0! | I23: =SUM(I19:I22) -> 0 | J23: =averageif(J19:J22,">0") -> #DIV/0! | K23: =averageif(K19:K22,">0") -> #DIV/0! | L23: =SUM(L19:L22) -> 100000 | M23: =SUM(M19:M22) -> 0 | O23: =SUM(O19:O22) -> 0 | P23: =SUM(P19:P22) -> 0 | Q23: =averageif(Q19:Q22,">0") -> #DIV/0! | S23: =averageif(S19:S22,">0") -> #DIV/0! | T23: =averageif(T19:T22,">0") -> #DIV/0!
B25: 담당자 | C25: 매체분석 | I25: DB효율 | L25: 매출분석
C26: 작성시점 | D26: 노출량 | E26: 클릭 | F26: 클릭당 단가 (원) CPC (광고집행비/클릭) | G26: 클릭률 CTR (클릭/노출량) | H26: 주간 집행 광고비 | I26: DB수량 | J26: DB전환률 (DB수량/클릭) | K26: DB단가 (광고비/DB수량) | L26: 수당 매출 | M26: DB 클로징 건수 | N26: 비고 (고객이름, 메모 등) | O26: 판매수량 (객실 수) | P26: 판매수량 (동반 총인원) | Q26: 클로징률 (클로징건수/DB수량) | R26: 순이익(원) | S26: ROAS (매출/광고비)*100 | T26: ROI (순이익/광고비)*100
A27: 11월 4주 11/23~11/29 (토~금) | B27: 맥스 | G27: =iferror(E27/D27,"") | J27: =iferror(I27/E27,"") | K27: =iferror(H27/I27,"") | Q27: =iferror(M27/I27,"") | R27: =iferror(L27-H27,"") -> 0 | S27: =iferror(L27/H27,"") | T27: =iferror(R27/H27,"")
B28: 해리 | F28: =iferror(H28/E28,"") | G28: =iferror(E28/D28,"") | J28: =iferror(I28/E28,"") | K28: =iferror(H28/I28,"") | Q28: =iferror(M28/I28,"") | R28: =iferror(L28-H28,"") -> 0 | S28: =iferror(L28/H28,"") | T28: =iferror(R28/H28,"")
B29: 로즈 | F29: =iferror(H29/E29,"") | G29: =iferror(E29/D29,"") | J29: =iferror(I29/E29,"") | K29: =iferror(H29/I29,"") | L29: =200000-120000 -> 80000 | M29: 1 | N29: 정성예, (김주희환불) | O29: 1 | P29: 2 | Q29: =iferror(M29/I29,"") | R29: =iferror(L29-H29,"") -> 80000 | S29: =iferror(L29/H29,"") | T29: =iferror(R29/H29,"")
B30: 페르 | F30: =iferror(H30/E30,"") | G30: =iferror(E30/D30,"") | J30: =iferror(I30/E30,"") | K30: =iferror(H30/I30,"") | Q30: =iferror(M30/I30,"") | R30: =iferror(L30-H30,"") -> 0 | S30: =iferror(L30/H30,"") | T30: =iferror(R30/H30,"")
A31: 팀평균 | F31: =averageif(F27:F30,">0") -> #DIV/0! | G31: =averageif(G27:G30,">0") -> #DIV/0! | I31: =SUM(I27:I30) -> 0 | J31: =averageif(J27:J30,">0") -> #DIV/0! | K31: =averageif(K27:K30,">0") -> #DIV/0! | L31: =SUM(L27:L30) -> 80000 | M31: =SUM(M27:M30) -> 1 | O31: =SUM(O27:O30) -> 1 | P31: =SUM(P27:P30) -> 2 | Q31: =averageif(Q27:Q30,">0") -> #DIV/0! | S31: =averageif(S27:S30,">0") -> #DIV/0! | T31: =averageif(T27:T30,">0") -> #DIV/0!
A33: 11월 | B33: 담당자 | C33: 매체분석 | I33: DB효율 | L33: 매출분석
C34: 작성시점 | D34: 노출량 | E34: 클릭 | F34: 클릭당 단가 (원) CPC (광고집행비/클릭) | G34: 클릭률 CTR (클릭/노출량) | H34: 월간 집행 광고비 | I34: DB수량 | J34: DB전환률 (DB수량/클릭) | K34: DB단가 (광고비/DB수량) | L34: 수당 매출 | M34: DB 클로징 건수 | N34: 비고 (고객이름, 메모 등) | O34: 판매수량 (객실 수) | P34: 판매수량 (동반 총인원) | Q34: 클로징률 (클로징건수/DB수량) | R34: 순이익(원) | S34: ROAS (매출/광고비)*100 | T34: ROI (순이익/광고비)*100
A35: 11월 통계 | B35: 맥스 | D35: =D3+D11+D19+D27 -> 0 | E35: =E3+E11+E19+E27 -> 0 | F35: =iferror(H35/E35,"") | G35: =iferror(E35/D35,"") | H35: =H3+H11+H19+H27 -> 0 | I35: =I3+I11+I19+I27 -> 0 | J35: =iferror(I35/E35,"") | K35: =iferror(H35/I35,"") | L35: =L3+L11+L19+L27 -> 200000 | M35: =M3+M11+M19+M27 -> 1 | O35: =O3+O11+O19+O27 -> 0 | P35: =P3+P11+P19+P27 -> 0 | Q35: =iferror(M35/I35,"") | R35: =iferror(L35-H35,"") -> 200000 | S35: =iferror(L35/H35,"") | T35: =iferror(R35/H35,"")
B36: 해리 | D36: =D4+D12+D20+D28 -> 0 | E36: =E4+E12+E20+E28 -> 0 | F36: =iferror(H36/E36,"") | G36: =iferror(E36/D36,"") | H36: =H4+H12+H20+H28 -> 0 | I36: =I4+I12+I20+I28 -> 0 | J36: =iferror(I36/E36,"") | K36: =iferror(H36/I36,"") | L36: =L4+L12+L20+L28 -> 280000 | M36: =M4+M12+M20+M28 -> 2 | O36: =O4+O12+O20+O28 -> 2 | P36: =P4+P12+P20+P28 -> 4 | Q36: =iferror(M36/I36,"") | R36: =iferror(L36-H36,"") -> 280000 | S36: =iferror(L36/H36,"") | T36: =iferror(R36/H36,"")
B37: 로즈 | D37: =D5+D13+D21+D29 -> 0 | E37: =E5+E13+E21+E29 -> 0 | F37: =iferror(H37/E37,"") | G37: =iferror(E37/D37,"") | H37: =H5+H13+H21+H29 -> 0 | I37: =I5+I13+I21+I29 -> 0 | J37: =iferror(I37/E37,"") | K37: =iferror(H37/I37,"") | L37: =L5+L13+L21+L29 -> 1100000 | M37: =M5+M13+M21+M29 -> 4 | O37: =O5+O13+O21+O29 -> 6 | P37: =P5+P13+P21+P29 -> 12 | Q37: =iferror(M37/I37,"") | R37: =iferror(L37-H37,"") -> 1100000 | S37: =iferror(L37/H37,"") | T37: =iferror(R37/H37,"")
B38: 페르 | D38: =D6+D14+D22+D30 -> 0 | E38: =E6+E14+E22+E30 -> 0 | F38: =iferror(H38/E38,"") | G38: =iferror(E38/D38,"") | H38: =H6+H14+H22+H30 -> 0 | I38: =I6+I14+I22+I30 -> 0 | J38: =iferror(I38/E38,"") | K38: =iferror(H38/I38,"") | L38: =L6+L14+L22+L30 -> 0 | M38: =M6+M14+M22+M30 -> 0 | O38: =O6+O14+O22+O30 -> 0 | P38: =P6+P14+P22+P30 -> 0 | Q38: =iferror(M38/I38,"") | R38: =iferror(L38-H38,"") -> 0 | S38: =iferror(L38/H38,"") | T38: =iferror(R38/H38,"")
A39: 팀평균 | F39: =averageif(F35:F38,">0") -> #DIV/0! | G39: =averageif(G35:G38,">0") -> #DIV/0! | I39: =SUM(I35:I38) -> 0 | J39: =averageif(J35:J38,">0") -> #DIV/0! | K39: =averageif(K35:K38,">0") -> #DIV/0! | L39: =SUM(L35:L38) -> 1580000 | M39: =SUM(M35:M38) -> 7 | O39: =SUM(O35:O38) -> 8 | P39: =SUM(P35:P38) -> 16 | Q39: =averageif(Q35:Q38,">0") -> #DIV/0! | S39: =averageif(S35:S38,">0") -> #DIV/0! | T39: =averageif(T35:T38,">0") -> #DIV/0!
A41: 9~11월 | B41: 담당자 | C41: 매체분석 | I41: DB효율 | L41: 매출분석
C42: 작성시점 | D42: 노출량 | E42: 클릭 | F42: 클릭당 단가 (원) CPC (광고집행비/클릭) | G42: 클릭률 CTR (클릭/노출량) | H42: 월간 집행 광고비 | I42: DB수량 | J42: DB전환률 (DB수량/클릭) | K42: DB단가 (광고비/DB수량) | L42: 수당 매출 | M42: DB 클로징 건수 | N42: 비고 (고객이름, 메모 등) | O42: 판매수량 (객실 수) | P42: 판매수량 (동반 총인원) | Q42: 클로징률 (클로징건수/DB수량) | R42: 순이익(원) | S42: ROAS (매출/광고비)*100 | T42: ROI (순이익/광고비)*100
A43: 홍일 크루즈 판매 통계 | B43: 맥스 | D43: =D35+'10월'!D51 -> 34248 | E43: =E35+'10월'!E51 -> 1522 | F43: =iferror(H43/E43,"") -> 353.14389 | G43: =iferror(E43/D43,"") -> 0.044440551 | H43: =H35+'10월'!H51 -> 537485 | I43: =I35+'10월'!I51 -> 119 | J43: =iferror(I43/E43,"") -> 0.078186597 | K43: =iferror(H43/I43,"") -> 4516.6807 | L43: =L35+'10월'!L51 -> 940000 | M43: =M35+'10월'!M51 -> 7 | O43: =O35+'10월'!O51 -> 6 | P43: =P35+'10월'!P51 -> 9 | Q43: =iferror(M43/I43,"") -> 0.058823529 | R43: =iferror(L43-H43,"") -> 402515 | S43: =iferror(L43/H43,"") -> 1.748886 | T43: =iferror(R43/H43,"") -> 0.74888602
B44: 해리 | D44: =D36+'10월'!D52 -> 30945 | E44: =E36+'10월'!E52 -> 1363 | F44: =iferror(H44/E44,"") -> 381.25312 | G44: =iferror(E44/D44,"") -> 0.044045888 | H44: =H36+'10월'!H52 -> 519648 | I44: =I36+'10월'!I52 -> 231 | J44: =iferror(I44/E44,"") -> 0.16947909 | K44: =iferror(H44/I44,"") -> 2249.5584 | L44: =L36+'10월'!L52 -> 2480000 | M44: =M36+'10월'!M52 -> 13 | O44: =O36+'10월'!O52 -> 18 | P44: =P36+'10월'!P52 -> 36 | Q44: =iferror(M44/I44,"") -> 0.056277056 | R44: =iferror(L44-H44,"") -> 1960352 | S44: =iferror(L44/H44,"") -> 4.7724614 | T44: =iferror(R44/H44,"") -> 3.7724614
B45: 로즈 | D45: =D37+'10월'!D53 -> 78644 | E45: =E37+'10월'!E53 -> 4665 | F45: =iferror(H45/E45,"") -> 256.612 | G45: =iferror(E45/D45,"") -> 0.059317939 | H45: =H37+'10월'!H53 -> 1197095 | I45: =I37+'10월'!I53 -> 415 | J45: =iferror(I45/E45,"") -> 0.088960343 | K45: =iferror(H45/I45,"") -> 2884.5663 | L45: =L37+'10월'!L53 -> 3300000 | M45: =M37+'10월'!M53 -> 20 | O45: =O37+'10월'!O53 -> 22 | P45: =P37+'10월'!P53 -> 44 | Q45: =iferror(M45/I45,"") -> 0.048192771 | R45: =iferror(L45-H45,"") -> 2102905 | S45: =iferror(L45/H45,"") -> 2.7566734 | T45: =iferror(R45/H45,"") -> 1.7566734
...

Sheet 10월
A1: 10월 | B1: 담당자 | C1: 매체분석 | I1: DB효율 | L1: 매출분석
C2: 작성시점 | D2: 노출량 | E2: 클릭 | F2: 클릭당 단가 (원) CPC (광고집행비/클릭) | G2: 클릭률 CTR (클릭/노출량) | H2: 주간 집행 광고비 | I2: DB수량 | J2: DB전환률 (DB수량/클릭) | K2: DB단가 (광고비/DB수량) | L2: 수당 매출 | M2: DB 클로징 건수 | N2: 비고 (고객이름, 메모 등) | O2: 판매수량 (객실 수) | P2: 판매수량 (동반 총인원) | Q2: 클로징률 (클로징건수/DB수량) | R2: 순이익(원) | S2: ROAS (매출/광고비)*100 | T2: ROI (순이익/광고비)*100
A3: 10월 1주 9/29~10/4 (토~금) | B3: 맥스 | C3: 45569 | D3: 1848 | E3: 84 | F3: 436 | G3: =iferror(E3/D3,"") -> 0.045454545 | H3: 19823 | I3: 4 | J3: =iferror(I3/E3,"") -> 0.047619048 | K3: =iferror(H3/I3,"") -> 4955.75 | L3: 60000 | M3: 1 | N3: 박선규(조인) | O3: 1 | P3: 1 | Q3: =iferror(M3/I3,"") -> 0.25 | R3: =iferror(L3-H3,"") -> 40177 | S3: =iferror(L3/H3,"") -> 3.0267871 | T3: =iferror(R3/H3,"") -> 2.0267871
B4: 해리 | C4: 45567 | D4: 0 | E4: 0 | F4: =iferror(H4/E4,"") | G4: =iferror(E4/D4,"") | H4: 0 | I4: 21 | J4: =iferror(I4/E4,"") | K4: =iferror(H4/I4,"") -> 0 | L4: 400000 | M4: 1 | N4: 이상현 지인 | O4: 2 | P4: 4 | Q4: =iferror(M4/I4,"") -> 0.047619048 | R4: =iferror(L4-H4,"") -> 400000 | S4: =iferror(L4/H4,"") | T4: =iferror(R4/H4,"")
B5: 로즈 | C5: ~10/4까지 | D5: 5363 | E5: 263 | F5: =iferror(H5/E5,"") -> 333 | G5: =iferror(E5/D5,"") -> 0.049039717 | H5: 87579 | I5: 21 | J5: =iferror(I5/E5,"") -> 0.079847909 | K5: =iferror(H5/I5,"") -> 4170.4286 | L5: 480000 | M5: 3 | N5: 서윤경, 박정섭. 정춘자(패) | O5: 3 | P5: 6 | Q5: =iferror(M5/I5,"") -> 0.14285714 | R5: =iferror(L5-H5,"") -> 392421 | S5: =iferror(L5/H5,"") -> 5.4807659 | T5: =iferror(R5/H5,"") -> 4.4807659
B6: 페르 | F6: =iferror(H6/E6,"") | G6: =iferror(E6/D6,"") | J6: =iferror(I6/E6,"") | K6: =iferror(H6/I6,"") | Q6: =iferror(M6/I6,"") | R6: =iferror(L6-H6,"") -> 0 | S6: =iferror(L6/H6,"") | T6: =iferror(R6/H6,"")
A7: 팀평균 | F7: =averageif(F3:F6,">0") -> 384.5 | G7: =averageif(G3:G6,">0") -> 0.047247131 | I7: =SUM(I3:I6) -> 46 | J7: =averageif(J3:J6,">0") -> 0.063733478 | K7: =averageif(K3:K6,">0") -> 4563.0893 | L7: =SUM(L3:L6) -> 940000 | M7: =SUM(M3:M6) -> 5 | O7: =SUM(O3:O6) -> 6 | P7: =SUM(P3:P6) -> 11 | Q7: =averageif(Q3:Q6,">0") -> 0.1468254 | S7: =averageif(S3:S6,">0") -> 4.2537765 | T7: =averageif(T3:T6,">0") -> 3.2537765
A9: 10월 | B9: 담당자 | C9: 매체분석 | I9: DB효율 | L9: 매출분석
C10: 작성시점 | D10: 노출량 | E10: 클릭 | F10: 클릭당 단가 (원) CPC (광고집행비/클릭) | G10: 클릭률 CTR (클릭/노출량) | H10: 주간 집행 광고비 | I10: DB수량 | J10: DB전환률 (DB수량/클릭) | K10: DB단가 (광고비/DB수량) | L10: 수당 매출 | M10: DB 클로징 건수 | N10: 비고 (고객이름, 메모 등) | O10: 판매수량 (객실 수) | P10: 판매수량 (동반 총인원) | Q10: 클로징률 (클로징건수/DB수량) | R10: 순이익(원) | S10: ROAS (매출/광고비)*100 | T10: ROI (순이익/광고비)*100
A11: 10월 2주 10/5~10/11 (토~금) | B11: 맥스 | C11: 45576 | D11: 9469 | E11: 445 | F11: 311 | G11: =iferror(E11/D11,"") -> 0.046995459 | H11: 138401 | I11: 36 | J11: =iferror(I11/E11,"") -> 0.080898876 | K11: =iferror(H11/I11,"") -> 3844.4722 | L11: 120000 | M11: 1 | N11: 심순애 | O11: 1 | P11: 2 | Q11: =iferror(M11/I11,"") -> 0.027777778 | R11: =iferror(L11-H11,"") -> -18401 | S11: =iferror(L11/H11,"") -> 0.86704576 | T11: =iferror(R11/H11,"") -> -0.13295424
B12: 해리 | C12: 45572 | D12: 0 | E12: 0 | F12: =iferror(H12/E12,"") | G12: =iferror(E12/D12,"") | H12: 0 | I12: 42 | J12: =iferror(I12/E12,"") | K12: =iferror(H12/I12,"") -> 0 | Q12: =iferror(M12/I12,"") -> 0 | R12: =iferror(L12-H12,"") -> 0 | S12: =iferror(L12/H12,"") | T12: =iferror(R12/H12,"")
B13: 로즈 | C13: 45576 | D13: 7091 | E13: 397 | F13: =iferror(H13/E13,"") -> 302.65995 | G13: =iferror(E13/D13,"") -> 0.055986462 | H13: 120156 | I13: 32 | J13: =iferror(I13/E13,"") -> 0.080604534 | K13: =iferror(H13/I13,"") -> 3754.875 | Q13: =iferror(M13/I13,"") -> 0 | R13: =iferror(L13-H13,"") -> -120156 | S13: =iferror(L13/H13,"") -> 0 | T13: =iferror(R13/H13,"") -> -1
B14: 페르 | F14: =iferror(H14/E14,"") | G14: =iferror(E14/D14,"") | J14: =iferror(I14/E14,"") | K14: =iferror(H14/I14,"") | Q14: =iferror(M14/I14,"") | R14: =iferror(L14-H14,"") -> 0 | S14: =iferror(L14/H14,"") | T14: =iferror(R14/H14,"")
A15: 팀평균 | F15: =averageif(F11:F14,">0") -> 306.82997 | G15: =averageif(G11:G14,">0") -> 0.05149096 | I15: =SUM(I11:I14) -> 110 | J15: =averageif(J11:J14,">0") -> 0.080751705 | K15: =averageif(K11:K14,">0") -> 3799.6736 | L15: =SUM(L11:L14) -> 120000 | M15: =SUM(M11:M14) -> 1 | O15: =SUM(O11:O14) -> 1 | P15: =SUM(P12:P14) -> 0 | Q15: =averageif(Q11:Q14,">0") -> 0.027777778 | S15: =averageif(S11:S14,">0") -> 0.86704576 | T15: =averageif(T11:T14,">0") -> #DIV/0!
A17: 10월 | B17: 담당자 | C17: 매체분석 | I17: DB효율 | L17: 매출분석
C18: 작성시점 | D18: 노출량 | E18: 클릭 | F18: 클릭당 단가 (원) CPC (광고집행비/클릭) | G18: 클릭률 CTR (클릭/노출량) | H18: 주간 집행 광고비 | I18: DB수량 | J18: DB전환률 (DB수량/클릭) | K18: DB단가 (광고비/DB수량) | L18: 수당 매출 | M18: DB 클로징 건수 | N18: 비고 (고객이름, 메모 등) | O18: 판매수량 (객실 수) | P18: 판매수량 (동반 총인원) | Q18: 클로징률 (클로징건수/DB수량) | R18: 순이익(원) | S18: ROAS (매출/광고비)*100 | T18: ROI (순이익/광고비)*100
A19: 10월 3주 10/12~10/18 (토~금) | B19: 맥스 | C19: 45583 | D19: 8785 | E19: 344 | F19: 374 | G19: =iferror(E19/D19,"") -> 0.039157655 | H19: 128540 | I19: 27 | J19: =iferror(I19/E19,"") -> 0.078488372 | K19: =iferror(H19/I19,"") -> 4760.7407 | L19: 120000 | M19: 1 | N19: 최철 | O19: 1 | P19: 2 | Q19: =iferror(M19/I19,"") -> 0.037037037 | R19: =iferror(L19-H19,"") -> -8540 | S19: =iferror(L19/H19,"") -> 0.93356154 | T19: =iferror(R19/H19,"") -> -0.066438463
B20: 해리 | C20: 45580 | D20: 2946 | E20: 182 | F20: =iferror(H20/E20,"") -> 268.10989 | G20: =iferror(E20/D20,"") -> 0.061778683 | H20: 48796 | I20: 12 | J20: =iferror(I20/E20,"") -> 0.065934066 | K20: =iferror(H20/I20,"") -> 4066.3333 | Q20: =iferror(M20/I20,"") -> 0 | R20: =iferror(L20-H20,"") -> -48796 | S20: =iferror(L20/H20,"") -> 0 | T20: =iferror(R20/H20,"") -> -1
B21: 로즈 | C21: ~10/18까지 | D21: 12208 | E21: 505 | F21: =iferror(H21/E21,"") -> 288.51287 | G21: =iferror(E21/D21,"") -> 0.041366317 | H21: 145699 | I21: 39 | J21: =iferror(I21/E21,"") -> 0.077227723 | K21: =iferror(H21/I21,"") -> 3735.8718 | L21: 400000 | M21: 1 | N21: 페르DB9개포함값 | O21: 2 | P21: 4 | Q21: =iferror(M21/I21,"") -> 0.025641026 | R21: =iferror(L21-H21,"") -> 254301 | S21: =iferror(L21/H21,"") -> 2.745386 | T21: =iferror(R21/H21,"") -> 1.745386
B22: 페르 | F22: =iferror(H22/E22,"") | G22: =iferror(E22/D22,"") | J22: =iferror(I22/E22,"") | K22: =iferror(H22/I22,"") | Q22: =iferror(M22/I22,"") | R22: =iferror(L22-H22,"") -> 0 | S22: =iferror(L22/H22,"") | T22: =iferror(R22/H22,"")
A23: 팀평균 | F23: =averageif(F19:F22,">0") -> 310.20759 | G23: =averageif(G19:G22,">0") -> 0.047434218 | I23: =SUM(I19:I22) -> 78 | J23: =averageif(J19:J22,">0") -> 0.073883387 | K23: =averageif(K19:K22,">0") -> 4187.6486 | L23: =SUM(L19:L22) -> 520000 | M23: =SUM(M19:M22) -> 2 | O23: =SUM(O19:O22) -> 3 | P23: =SUM(P19:P22) -> 6 | Q23: =averageif(Q19:Q22,">0") -> 0.031339031 | S23: =averageif(S19:S22,">0") -> 1.8394738 | T23: =averageif(T19:T22,">0") -> 1.745386
A25: 10월 | B25: 담당자 | C25: 매체분석 | I25: DB효율 | L25: 매출분석
C26: 작성시점 | D26: 노출량 | E26: 클릭 | F26: 클릭당 단가 (원) CPC (광고집행비/클릭) | G26: 클릭률 CTR (클릭/노출량) | H26: 주간 집행 광고비 | I26: DB수량 | J26: DB전환률 (DB수량/클릭) | K26: DB단가 (광고비/DB수량) | L26: 수당 매출 | M26: DB 클로징 건수 | N26: 비고 (고객이름, 메모 등) | O26: 판매수량 (객실 수) | P26: 판매수량 (동반 총인원) | Q26: 클로징률 (클로징건수/DB수량) | R26: 순이익(원) | S26: ROAS (매출/광고비)*100 | T26: ROI (순이익/광고비)*100
A27: 10월 4주 10/19~10/25 (토~금) | B27: 맥스 | C27: 45590 | D27: 5154 | E27: 217 | F27: 305 | G27: =iferror(E27/D27,"") -> 0.042103221 | H27: 66229 | I27: 10 | J27: =iferror(I27/E27,"") -> 0.046082949 | K27: =iferror(H27/I27,"") -> 6622.9 | L27: 120000 | M27: 1 | N27: 유진경,최진주 | O27: 1 | P27: 2 | Q27: =iferror(M27/I27,"") -> 0.1 | R27: =iferror(L27-H27,"") -> 53771 | S27: =iferror(L27/H27,"") -> 1.8118951 | T27: =iferror(R27/H27,"") -> 0.81189509
B28: 해리 | F28: =iferror(H28/E28,"") | G28: =iferror(E28/D28,"") | J28: =iferror(I28/E28,"") | K28: =iferror(H28/I28,"") | Q28: =iferror(M28/I28,"") | R28: =iferror(L28-H28,"") -> 0 | S28: =iferror(L28/H28,"") | T28: =iferror(R28/H28,"")
B29: 로즈 | C29: 45587 | D29: 3738 | E29: 177 | F29: =iferror(H29/E29,"") -> 305.96045 | G29: =iferror(E29/D29,"") -> 0.047351525 | H29: 54155 | I29: 12 | J29: =iferror(I29/E29,"") -> 0.06779661 | K29: =iferror(H29/I29,"") -> 4512.9167 | Q29: =iferror(M29/I29,"") -> 0 | R29: =iferror(L29-H29,"") -> -54155 | S29: =iferror(L29/H29,"") -> 0 | T29: =iferror(R29/H29,"") -> -1
B30: 페르 | F30: =iferror(H30/E30,"") | G30: =iferror(E30/D30,"") | J30: =iferror(I30/E30,"") | K30: =iferror(H30/I30,"") | Q30: =iferror(M30/I30,"") | R30: =iferror(L30-H30,"") -> 0 | S30: =iferror(L30/H30,"") | T30: =iferror(R30/H30,"")
A31: 팀평균 | F31: =averageif(F27:F30,">0") -> 305.48023 | G31: =averageif(G27:G30,">0") -> 0.044727373 | I31: =SUM(I27:I30) -> 22 | J31: =averageif(J27:J30,">0") -> 0.05693978 | K31: =averageif(K27:K30,">0") -> 5567.9083 | L31: =SUM(L27:L30) -> 120000 | M31: =SUM(M27:M30) -> 1 | O31: =SUM(O27:O30) -> 1 | P31: =SUM(P27:P30) -> 2 | Q31: =averageif(Q27:Q30,">0") -> 0.1 | S31: =averageif(S27:S30,">0") -> 1.8118951 | T31: =averageif(T27:T30,">0") -> 0.81189509
A33: 10월 | B33: 담당자 | C33: 매체분석 | I33: DB효율 | L33: 매출분석
C34: 작성시점 | D34: 노출량 | E34: 클릭 | F34: 클릭당 단가 (원) CPC (광고집행비/클릭) | G34: 클릭률 CTR (클릭/노출량) | H34: 주간 집행 광고비 | I34: DB수량 | J34: DB전환률 (DB수량/클릭) | K34: DB단가 (광고비/DB수량) | L34: 수당 매출 | M34: DB 클로징 건수 | N34: 비고 (고객이름, 메모 등) | O34: 판매수량 (객실 수) | P34: 판매수량 (동반 총인원) | Q34: 클로징률 (클로징건수/DB수량) | R34: 순이익(원) | S34: ROAS (매출/광고비)*100 | T34: ROI (순이익/광고비)*100
A35: 10월 5주 10/26~11/1 (토~금) | B35: 맥스 | F35: =iferror(H35/E35,"") | G35: =iferror(E35/D35,"") | J35: =iferror(I35/E35,"") | K35: =iferror(H35/I35,"") | Q35: =iferror(M35/I35,"") | R35: =iferror(L35-H35,"") -> 0 | S35: =iferror(L35/H35,"") | T35: =iferror(R35/H35,"")
B36: 해리 | F36: =iferror(H36/E36,"") | G36: =iferror(E36/D36,"") | J36: =iferror(I36/E36,"") | K36: =iferror(H36/I36,"") | L36: 120000 | M36: 1 | N36: 최원주 | O36: 1 | P36: 2 | Q36: =iferror(M36/I36,"") | R36: =iferror(L36-H36,"") -> 120000 | S36: =iferror(L36/H36,"") | T36: =iferror(R36/H36,"")
B37: 로즈 | F37: =iferror(H37/E37,"") | G37: =iferror(E37/D37,"") | J37: =iferror(I37/E37,"") | K37: =iferror(H37/I37,"") | Q37: =iferror(M37/I37,"") | R37: =iferror(L37-H37,"") -> 0 | S37: =iferror(L37/H37,"") | T37: =iferror(R37/H37,"")
B38: 페르 | F38: =iferror(H38/E38,"") | G38: =iferror(E38/D38,"") | J38: =iferror(I38/E38,"") | K38: =iferror(H38/I38,"") | Q38: =iferror(M38/I38,"") | R38: =iferror(L38-H38,"") -> 0 | S38: =iferror(L38/H38,"") | T38: =iferror(R38/H38,"")
A39: 팀평균 | F39: =averageif(F35:F38,">0") -> #DIV/0! | G39: =averageif(G35:G38,">0") -> #DIV/0! | I39: =SUM(I35:I38) -> 0 | J39: =averageif(J35:J38,">0") -> #DIV/0! | K39: =averageif(K35:K38,">0") -> #DIV/0! | L39: =SUM(L35:L38) -> 120000 | M39: =SUM(M35:M38) -> 1 | O39: =SUM(O35:O38) -> 1 | P39: =SUM(P35:P38) -> 2 | Q39: =averageif(Q35:Q38,">0") -> #DIV/0! | S39: =averageif(S35:S38,">0") -> #DIV/0! | T39: =averageif(T35:T38,">0") -> #DIV/0!
A41: 10월 | B41: 담당자 | C41: 매체분석 | I41: DB효율 | L41: 매출분석
C42: 작성시점 | D42: 노출량 | E42: 클릭 | F42: 클릭당 단가 (원) CPC (광고집행비/클릭) | G42: 클릭률 CTR (클릭/노출량) | H42: 월간 집행 광고비 | I42: DB수량 | J42: DB전환률 (DB수량/클릭) | K42: DB단가 (광고비/DB수량) | L42: 수당 매출 | M42: DB 클로징 건수 | N42: 비고 (고객이름, 메모 등) | O42: 판매수량 (객실 수) | P42: 판매수량 (동반 총인원) | Q42: 클로징률 (클로징건수/DB수량) | R42: 순이익(원) | S42: ROAS (매출/광고비)*100 | T42: ROI (순이익/광고비)*100
A43: 10월 통계 | B43: 맥스 | D43: =D3+D11+D19+D27+D35 -> 25256 | E43: =E3+E11+E19+E27+E35 -> 1090 | F43: =iferror(H43/E43,"") -> 323.84679 | G43: =iferror(E43/D43,"") -> 0.043158061 | H43: =H3+H11+H19+H27+H35 -> 352993 | I43: =I3+I11+I19+I27+I35 -> 77 | J43: =iferror(I43/E43,"") -> 0.070642202 | K43: =iferror(H43/I43,"") -> 4584.3247 | L43: =L3+L11+L19+L27+L35 -> 420000 | M43: =M3+M11+M19+M27+M35 -> 4 | O43: =O3+O11+O19+O27+O35 -> 4 | P43: =P3+P13+P19+P27+P35 -> 5 | Q43: =iferror(M43/I43,"") -> 0.051948052 | R43: =iferror(L43-H43,"") -> 67007 | S43: =iferror(L43/H43,"") -> 1.1898253 | T43: =iferror(R43/H43,"") -> 0.18982529
